<?xml version="1.0" encoding="utf-8"?>
<!-- This URDF was automatically created by SolidWorks to URDF Exporter! Originally created by Stephen Brawner (brawner@gmail.com) 
     Commit Version: 1.6.0-4-g7f85cfe  Build Version: 1.6.7995.38578
     For more information, please see http://wiki.ros.org/sw_urdf_exporter -->
<robot
  name="Embodied lifting robot_two wheels_RM75-B-V">
  <link
    name="base_link">
    <inertial>
      <origin
        xyz="0.0156 -0.0013 0.1404"
        rpy="0 0 0" />
      <mass
        value="85" />
      <inertia
        ixx="13.992"
        ixy="-0.082"
        ixz="0.5258"
        iyy="15.43"
        iyz="0.04155"
        izz="3.329" />
    </inertial>
    <visual>
      <origin
        xyz="0 0 0"
        rpy="-1.57 0 0" />
      <geometry>
        <mesh
          filename="package://Embodied lifting robot_two wheels_RM75-B-V/meshes/base_link.STL" />
      </geometry>
      <material
        name="">
        <color
          rgba="1 1 1 1" />
      </material>
    </visual>
    <collision>
      <origin
        xyz="0 0 0"
        rpy="0 0 0" />
      <geometry>
        <mesh
          filename="package://Embodied lifting robot_two wheels_RM75-B-V/meshes/base_link.STL" />
      </geometry>
    </collision>
  </link>
  <link
    name="link_5">
    <inertial>
      <origin
        xyz="4E-06 -0.095859 0.14848"
        rpy="0 0 0" />
      <mass
        value="11" />
      <inertia
        ixx="0.092858272"
        ixy="2.2E-05"
        ixz="-1.1585E-05"
        iyy="0.146075845"
        iyz="-2.77942E-04"
        izz="0.118670960" />
    </inertial>
    <visual>
      <origin
        xyz="0 0 0"
        rpy="-1.57 0 0" />
      <geometry>
        <mesh
          filename="package://Embodied lifting robot_two wheels_RM75-B-V/meshes/link_5.STL" />
      </geometry>
      <material
        name="">
        <color
          rgba="1 1 1 1" />
      </material>
    </visual>
    <collision>
      <origin
        xyz="0 0 0"
        rpy="0 0 0" />
      <geometry>
        <mesh
          filename="package://Embodied lifting robot_two wheels_RM75-B-V/meshes/link_5.STL" />
      </geometry>
    </collision>
  </link>
  <joint
    name="joint_5"
    type="prismatic">
    <origin
      xyz="0.28339 0 0.17234"
      rpy="0 0 -1.5708" />
    <parent
      link="base_link" />
    <child
      link="link_5" />
    <axis
      xyz="0 0 -1" />
    <limit
      lower="-0.75"
      upper="-0.75"
      effort="0"
      velocity="0.001" />
  </joint>
  <link
    name="link_left_0">
    <inertial>
      <origin
        xyz="0.00017015 4.8354E-09 0.077978"
        rpy="0 0 0" />
      <mass
        value="0.33723" />
      <inertia
        ixx="0.00047403"
        ixy="-2.9684E-12"
        ixz="0"
        iyy="0.00047403"
        iyz="-6.211E-11"
        izz="0.00050951" />
    </inertial>
    <visual>
      <origin
        xyz="0 0 0"
        rpy="-1.57 0 0" />
      <geometry>
        <mesh
          filename="package://Embodied lifting robot_two wheels_RM75-B-V/meshes/link_left_0.STL" />
      </geometry>
      <material
        name="">
        <color
          rgba="0.89804 0.91765 0.92941 1" />
      </material>
    </visual>
    <collision>
      <origin
        xyz="0 0 0"
        rpy="0 0 0" />
      <geometry>
        <mesh
          filename="package://Embodied lifting robot_two wheels_RM75-B-V/meshes/link_left_0.STL" />
      </geometry>
    </collision>
  </link>
  <link
    name="link_right_0">
    <inertial>
      <origin
        xyz="-0.00001 0 -0.091692"
        rpy="0 0 0" />
      <mass
        value="0.337" />
      <inertia
        ixx="0.000474035"
        ixy="0"
        ixz="0.00000001"
        iyy="0.000474026"
        iyz="0"
        izz="0.000509509" />
    </inertial>
    <visual>
      <origin
        xyz="0 0 0"
        rpy="-1.57 0 0" />
      <geometry>
        <mesh
          filename="package://Embodied lifting robot_two wheels_RM75-B-V/meshes/link_right_0.STL" />
      </geometry>
      <material
        name="">
        <color
          rgba="0.89804 0.91765 0.92941 1" />
      </material>
    </visual>
    <collision>
      <origin
        xyz="0 0 0"
        rpy="0 0 0" />
      <geometry>
        <mesh
          filename="package://Embodied lifting robot_two wheels_RM75-B-V/meshes/link_right_0.STL" />
      </geometry>
    </collision>
  </link>
  <joint
    name="joint_right_0"
    type="fixed">
    <origin
      xyz="0.062162 -0.059 0.13748"
      rpy="0 0.7854 0" />
    <parent
      link="link_5" />
    <child
      link="link_right_0" />
    <axis
      xyz="0 0 0" />
  </joint>
  <link
    name="link_right_1">
    <inertial>
      <origin
        xyz="0.000241 -0.013273 -0.00995"
        rpy="0 0 0" />
      <mass
        value="1.574" />
      <inertia
        ixx="0.002920666"
        ixy="1.4703E-05"
        ixz="-4.131E-06"
        iyy="0.002476942"
        iyz="-2.8462E-05"
        izz="0.001727926" />
    </inertial>
    <visual>
      <origin
        xyz="0 0 0"
        rpy="-1.57 0 0" />
      <geometry>
        <mesh
          filename="package://Embodied lifting robot_two wheels_RM75-B-V/meshes/link_right_1.STL" />
      </geometry>
      <material
        name="">
        <color
          rgba="0.79216 0.81961 0.93333 1" />
      </material>
    </visual>
    <collision>
      <origin
        xyz="0 0 0"
        rpy="0 0 0" />
      <geometry>
        <mesh
          filename="package://Embodied lifting robot_two wheels_RM75-B-V/meshes/link_right_1.STL" />
      </geometry>
    </collision>
  </link>
  <joint
    name="joint_right_1"
    type="revolute">
    <origin
      xyz="0 0 0.2405"
      rpy="0 0 0" />
    <parent
      link="link_right_0" />
    <child
      link="link_right_1" />
    <axis
      xyz="0 0 1" />
    <limit
      lower="-3.07"
      upper="3.07"
      effort="7"
      velocity="3.14" />
  </joint>
  <link
    name="link_right_2">
    <inertial>
      <origin
        xyz="-0.000357 -0.106798 0.005329"
        rpy="0 0 0" />
      <mass
        value="1.217" />
      <inertia
        ixx="0.017404207"
        ixy="-4.3488E-05"
        ixz="-3.297E-06"
        iyy="0.000927428"
        iyz="0.000108523"
        izz="0.01731977" />
    </inertial>
    <visual>
      <origin
        xyz="0 0 0"
        rpy="-1.57 0 0" />
      <geometry>
        <mesh
          filename="package://Embodied lifting robot_two wheels_RM75-B-V/meshes/link_right_2.STL" />
      </geometry>
      <material
        name="">
        <color
          rgba="0.79216 0.81961 0.93333 1" />
      </material>
    </visual>
    <collision>
      <origin
        xyz="0 0 0"
        rpy="0 0 0" />
      <geometry>
        <mesh
          filename="package://Embodied lifting robot_two wheels_RM75-B-V/meshes/link_right_2.STL" />
      </geometry>
    </collision>
  </link>
  <joint
    name="joint_right_2"
    type="revolute">
    <origin
      xyz="0 0 0"
      rpy="-1.5708 0 0" />
    <parent
      link="link_right_1" />
    <child
      link="link_right_2" />
    <axis
      xyz="0 0 1" />
    <limit
      lower="-2.26"
      upper="2.26"
      effort="7"
      velocity="3.14" />
  </joint>
  <link
    name="link_right_3">
    <inertial>
      <origin
        xyz="3E-06 -0.010398 -0.011324"
        rpy="0 0 0" />
      <mass
        value="1.11" />
      <inertia
        ixx="0.002099034"
        ixy="2.292E-06"
        ixz="-4.181E-06"
        iyy="0.001641235"
        iyz="-9.3542E-05"
        izz="0.001182557" />
    </inertial>
    <visual>
      <origin
        xyz="0 0 0"
        rpy="-1.57 0 0" />
      <geometry>
        <mesh
          filename="package://Embodied lifting robot_two wheels_RM75-B-V/meshes/link_right_3.STL" />
      </geometry>
      <material
        name="">
        <color
          rgba="0.79216 0.81961 0.93333 1" />
      </material>
    </visual>
    <collision>
      <origin
        xyz="0 0 0"
        rpy="0 0 0" />
      <geometry>
        <mesh
          filename="package://Embodied lifting robot_two wheels_RM75-B-V/meshes/link_right_3.STL" />
      </geometry>
    </collision>
  </link>
  <joint
    name="joint_right_3"
    type="revolute">
    <origin
      xyz="0 -0.256 0"
      rpy="1.5708 0 0" />
    <parent
      link="link_right_2" />
    <child
      link="link_right_3" />
    <axis
      xyz="0 0 1" />
    <limit
      lower="-3.07"
      upper="3.07"
      effort="7"
      velocity="3.925" />
  </joint>
  <link
    name="link_right_4">
    <inertial>
      <origin
        xyz="-5E-06 -0.084658 0.004747"
        rpy="0 0 0" />
      <mass
        value="0.685" />
      <inertia
        ixx="0.006204576"
        ixy="-8.19E-07"
        ixz="-6.15E-07"
        iyy="0.000388441"
        iyz="4.3054E-05"
        izz="0.006162881" />
    </inertial>
    <visual>
      <origin
        xyz="0 0 0"
        rpy="-1.57 0 0" />
      <geometry>
        <mesh
          filename="package://Embodied lifting robot_two wheels_RM75-B-V/meshes/link_right_4.STL" />
      </geometry>
      <material
        name="">
        <color
          rgba="0.79216 0.81961 0.93333 1" />
      </material>
    </visual>
    <collision>
      <origin
        xyz="0 0 0"
        rpy="0 0 0" />
      <geometry>
        <mesh
          filename="package://Embodied lifting robot_two wheels_RM75-B-V/meshes/link_right_4.STL" />
      </geometry>
    </collision>
  </link>
  <joint
    name="joint_right_4"
    type="revolute">
    <origin
      xyz="0 0 0"
      rpy="-1.5708 0 0" />
    <parent
      link="link_right_3" />
    <child
      link="link_right_4" />
    <axis
      xyz="0 0 1" />
    <limit
      lower="-2.355"
      upper="2.355"
      effort="7"
      velocity="3.925" />
  </joint>
  <link
    name="link_right_5">
    <inertial>
      <origin
        xyz="7.8E-05 -0.012937 -0.008781"
        rpy="0 0 0" />
      <mass
        value="0.619" />
      <inertia
        ixx="0.00077862"
        ixy="2.261E-06"
        ixz="-9.21E-07"
        iyy="0.00059017"
        iyz="-3.5324E-05"
        izz="0.00047386" />
    </inertial>
    <visual>
      <origin
        xyz="0 0 0"
        rpy="-1.57 0 0" />
      <geometry>
        <mesh
          filename="package://Embodied lifting robot_two wheels_RM75-B-V/meshes/link_right_5.STL" />
      </geometry>
      <material
        name="">
        <color
          rgba="0.79216 0.81961 0.93333 1" />
      </material>
    </visual>
    <collision>
      <origin
        xyz="0 0 0"
        rpy="0 0 0" />
      <geometry>
        <mesh
          filename="package://Embodied lifting robot_two wheels_RM75-B-V/meshes/link_right_5.STL" />
      </geometry>
    </collision>
  </link>
  <joint
    name="joint_right_5"
    type="revolute">
    <origin
      xyz="0 -0.21 0"
      rpy="1.5708 0 0" />
    <parent
      link="link_right_4" />
    <child
      link="link_right_5" />
    <axis
      xyz="0 0 1" />
    <limit
      lower="-3.07"
      upper="3.07"
      effort="7"
      velocity="3.925" />
  </joint>
  <link
    name="link_right_6">
    <inertial>
      <origin
        xyz="-1.4E-05 -0.078524 0.002819"
        rpy="0 0 0" />
      <mass
        value="0.602" />
      <inertia
        ixx="0.0044999"
        ixy="-8.02E-07"
        ixz="-4.44E-07"
        iyy="0.00029476"
        iyz="1.2831E-05"
        izz="0.0044783" />
    </inertial>
    <visual>
      <origin
        xyz="0 0 0"
        rpy="-1.57 0 0" />
      <geometry>
        <mesh
          filename="package://Embodied lifting robot_two wheels_RM75-B-V/meshes/link_right_6.STL" />
      </geometry>
      <material
        name="">
        <color
          rgba="0.79216 0.81961 0.93333 1" />
      </material>
    </visual>
    <collision>
      <origin
        xyz="0 0 0"
        rpy="0 0 0" />
      <geometry>
        <mesh
          filename="package://Embodied lifting robot_two wheels_RM75-B-V/meshes/link_right_6.STL" />
      </geometry>
    </collision>
  </link>
  <joint
    name="joint_right_6"
    type="revolute">
    <origin
      xyz="0 0 0"
      rpy="-1.5708 0 0" />
    <parent
      link="link_right_5" />
    <child
      link="link_right_6" />
    <axis
      xyz="0 0 1" />
    <limit
      lower="-2.2294"
      upper="2.2294"
      effort="7"
      velocity="3.925" />
  </joint>
  <link
    name="link_right_7">
    <inertial>
      <origin
        xyz="0.035573 -0.00393 -0.000086"
        rpy="0 0 0" />
      <mass
        value="0.25" />
      <inertia
        ixx="1.58188E-04"
        ixy="-5.565E-05"
        ixz="-3.8566E-05"
        iyy="4.99574E-04"
        iyz="-3.43E-06"
        izz="0.000579047" />
    </inertial>
    <visual>
      <origin
        xyz="0 0 0"
        rpy="-1.57 0 0" />
      <geometry>
        <mesh
          filename="package://Embodied lifting robot_two wheels_RM75-B-V/meshes/link_right_7.STL" />
      </geometry>
      <material
        name="">
        <color
          rgba="1 1 1 1" />
      </material>
    </visual>
    <collision>
      <origin
        xyz="0 0 0"
        rpy="0 0 0" />
      <geometry>
        <mesh
          filename="package://Embodied lifting robot_two wheels_RM75-B-V/meshes/link_right_7.STL" />
      </geometry>
    </collision>
  </link>
  <joint
    name="joint_right_7"
    type="revolute">
    <origin
      xyz="0 -0.144 0"
      rpy="1.5708 0 0" />
    <parent
      link="link_right_6" />
    <child
      link="link_right_7" />
    <axis
      xyz="0 0 -1" />
    <limit
      lower="-6.28"
      upper="6.28"
      effort="7"
      velocity="3.925" />
  </joint>
  <link
    name="link_right_camera">
    <inertial>
      <origin
        xyz="2.3289E-06 0.028317 -0.013522"
        rpy="0 0 0" />
      <mass
        value="0.08" />
      <inertia
        ixx="4.757E-05"
        ixy="2.2E-08"
        ixz="-2.2E-08"
        iyy="6.895E-06"
        iyz="9.66E-07"
        izz="4.6649E-05" />
    </inertial>
    <visual>
      <origin
        xyz="0 0 0"
        rpy="-1.57 0 0" />
      <geometry>
        <mesh
          filename="package://Embodied lifting robot_two wheels_RM75-B-V/meshes/link_right_camera.STL" />
      </geometry>
      <material
        name="">
        <color
          rgba="0.69804 0.69804 0.69804 1" />
      </material>
    </visual>
    <collision>
      <origin
        xyz="0 0 0"
        rpy="0 0 0" />
      <geometry>
        <mesh
          filename="package://Embodied lifting robot_two wheels_RM75-B-V/meshes/link_right_camera.STL" />
      </geometry>
    </collision>
  </link>
  <joint
    name="joint_right_camera"
    type="fixed">
    <origin
      xyz="0.085512 -0.044595 -0.01593"
      rpy="0 0 0" />
    <parent
      link="link_right_7" />
    <child
      link="link_right_camera" />
    <axis
      xyz="0 0 0" />
  </joint>

  <joint name="panda_hand_joint" type="fixed">
    <parent link="link_right_7"/>
    <child link="hand_base_link"/>
    <origin rpy="0 0 3.1415926" xyz="0 0 0"/>
  </joint>

   <link
    name="hand_base_link">
    <inertial>
      <origin
        xyz="-0.00160320773490556 0.000358462699237561 0.0538002704027215"
        rpy="0 0 0" />
      <mass
        value="0.06740077960995" />
      <inertia
        ixx="5.22359941041901E-05"
        ixy="3.0391535852764E-07"
        ixz="3.88322215371643E-07"
        iyy="3.33473043513648E-05"
        iyz="-7.77555280794861E-07"
        izz="2.28342677422006E-05" />
    </inertial>
    <visual>
      <origin
        xyz="0 0 0"
        rpy="-1.57079632 0 0" />
      <geometry>
        <mesh
          filename="meshes/hand_base_link.STL" />
      </geometry>
      <material
        name="">
        <color
          rgba="1 0.6 0 1" />
      </material>
    </visual>
    <collision>
      <origin
        xyz="0 0 0"
        rpy="0 0 0" />
      <geometry>
        <mesh
          filename="meshes/hand_base_link.STL" />
      </geometry>
    </collision>
  </link>
  <link
    name="thumb_metacarpals_base2">
    <inertial>
      <origin
        xyz="0.00162795738393507 0.00276671978336815 -0.00184227725602707"
        rpy="0 0 0" />
      <mass
        value="0.00138591070212997" />
      <inertia
        ixx="5.26294625624223E-08"
        ixy="-3.9288013799604E-09"
        ixz="2.43766268199571E-09"
        iyy="4.82623724532942E-08"
        iyz="3.71867754115443E-09"
        izz="2.88555522060562E-08" />
    </inertial>
    <visual>
      <origin
        xyz="0 0 0"
        rpy="-1.57079632 0 0" />
      <geometry>
        <mesh
          filename="meshes/thumb_metacarpals_base2.STL" />
      </geometry>
      <material
        name="">
        <color
          rgba="0.164705882352941 0.282352941176471 0.443137254901961 1" />
      </material>
    </visual>
    <collision>
      <origin
        xyz="0 0 0"
        rpy="0 0 0" />
      <geometry>
        <mesh
          filename="meshes/thumb_metacarpals_base2.STL" />
      </geometry>
    </collision>
  </link>
  <joint
    name="thumb_cmc_yaw"
    type="revolute">
    <origin
      xyz="0.011508 0.022975 0.032794"
      rpy="0 0 0" />
    <parent
      link="hand_base_link" />
    <child
      link="thumb_metacarpals_base2" />
    <axis
      xyz="0 0 -1" />
    <limit
      lower="0"
      upper="1.36"
      effort="100"
      velocity="1" />
  </joint>
  <link
    name="thumb_metacarpals">
    <inertial>
      <origin
        xyz="4.24920612856275E-05 -1.67885666835232E-05 0.0228341522590467"
        rpy="0 0 0" />
      <mass
        value="0.0123381607727595" />
      <inertia
        ixx="1.10292488693766E-06"
        ixy="-6.14241939151719E-10"
        ixz="1.14233108676795E-07"
        iyy="1.76757658485787E-06"
        iyz="-4.24576599367025E-10"
        izz="9.36348143657406E-07" />
    </inertial>
    <visual>
      <origin
        xyz="0 0 0"
        rpy="-1.57079632 0 0" />
      <geometry>
        <mesh
          filename="meshes/thumb_metacarpals.STL" />
      </geometry>
      <material
        name="">
        <color
          rgba="1 0.6 0 1" />
      </material>
    </visual>
    <collision>
      <origin
        xyz="0 0 0"
        rpy="0 0 0" />
      <geometry>
        <mesh
          filename="meshes/thumb_metacarpals.STL" />
      </geometry>
    </collision>
  </link>
  <joint
    name="thumb_cmc_pitch"
    type="revolute">
    <origin
      xyz="0.0061649 0.010678 -0.004891"
      rpy="0 -1.1529 -2.0944" />
    <parent
      link="thumb_metacarpals_base2" />
    <child
      link="thumb_metacarpals" />
    <axis
      xyz="0 1 0" />
    <limit
      lower="0"
      upper="0.58"
      effort="100"
      velocity="1" />
  </joint>
  <link
    name="thumb_distal">
    <inertial>
      <origin
        xyz="-0.00413690727496815 -4.54842793429222E-07 0.0230097179163771"
        rpy="0 0 0" />
      <mass
        value="0.00763302603723749" />
      <inertia
        ixx="1.30546842791578E-06"
        ixy="-2.61617511029467E-12"
        ixz="7.19030685242407E-08"
        iyy="1.22457212713176E-06"
        iyz="1.66931068485225E-11"
        izz="2.7729897944409E-07" />
    </inertial>
    <visual>
      <origin
        xyz="0 0 0"
        rpy="-1.57079632 0 0" />
      <geometry>
        <mesh
          filename="meshes/thumb_distal.STL" />
      </geometry>
      <material
        name="">
        <color
          rgba="0.792156862745098 0.792156862745098 0.792156862745098 1" />
      </material>
    </visual>
    <collision>
      <origin
        xyz="0 0 0"
        rpy="0 0 0" />
      <geometry>
        <mesh
          filename="meshes/thumb_distal.STL" />
      </geometry>
    </collision>
  </link>
  <joint
    name="thumb_ip"
    type="revolute">
    <origin
      xyz="0.0037776 0 0.045368"
      rpy="0 0 0" />
    <parent
      link="thumb_metacarpals" />
    <child
      link="thumb_distal" />
    <axis
      xyz="0 1 0" />
    <limit
      lower="0"
      upper="1.08"
      effort="100"
      velocity="1" />
    <mimic
      joint="thumb_cmc_pitch"
      multiplier="1.86"
      offset="0" />
  </joint>
  <link
    name="index_proximal">
    <inertial>
      <origin
        xyz="-0.00208665596033792 -4.8964990644329E-06 0.0172736718900068"
        rpy="0 0 0" />
      <mass
        value="0.00253178529301663" />
      <inertia
        ixx="2.65990159539482E-07"
        ixy="-3.55165625722842E-11"
        ixz="4.31046335852167E-08"
        iyy="2.72915460277804E-07"
        iyz="1.75935978708959E-10"
        izz="8.56026306687528E-08" />
    </inertial>
    <visual>
      <origin
        xyz="0 0 0"
        rpy="-1.57079632 0 0" />
      <geometry>
        <mesh
          filename="meshes/index_proximal.STL" />
      </geometry>
      <material
        name="">
        <color
          rgba="0.980392156862745 0.780392156862745 0.627450980392157 1" />
      </material>
    </visual>
    <collision>
      <origin
        xyz="0 0 0"
        rpy="0 0 0" />
      <geometry>
        <mesh
          filename="meshes/index_proximal.STL" />
      </geometry>
    </collision>
  </link>
  <joint
    name="index_mcp_pitch"
    type="revolute">
    <origin
      xyz="0.0024758 0.02419 0.098779"
      rpy="-0.05236 0 0" />
    <parent
      link="hand_base_link" />
    <child
      link="index_proximal" />
    <axis
      xyz="0 1 0" />
    <limit
      lower="0"
      upper="1.60"
      effort="100"
      velocity="1" />
  </joint>
  <link
    name="index_distal">
    <inertial>
      <origin
        xyz="0.00658940011630532 -4.59976557022623E-06 0.0194434136420913"
        rpy="0 0 0" />
      <mass
        value="0.00376787129082313" />
      <inertia
        ixx="3.22116619426455E-07"
        ixy="1.03152735699049E-11"
        ixz="-1.14363506430985E-07"
        iyy="3.65131844686317E-07"
        iyz="-1.97263639269362E-10"
        izz="1.24256890612907E-07" />
    </inertial>
    <visual>
      <origin
        xyz="0 0 0"
        rpy="-1.57079632 0 0" />
      <geometry>
        <mesh
          filename="meshes/index_distal.STL" />
      </geometry>
      <material
        name="">
        <color
          rgba="0.164705882352941 0.282352941176471 0.443137254901961 1" />
      </material>
    </visual>
    <collision>
      <origin
        xyz="0 0 0"
        rpy="0 0 0" />
      <geometry>
        <mesh
          filename="meshes/index_distal.STL" />
      </geometry>
    </collision>
  </link>
  <joint
    name="index_dip"
    type="revolute">
    <origin
      xyz="-0.0052516 0 0.036625"
      rpy="0 0 0" />
    <parent
      link="index_proximal" />
    <child
      link="index_distal" />
    <axis
      xyz="0 1 0" />
    <limit
      lower="0"
      upper="1.43"
      effort="100"
      velocity="1" />
    <mimic
      joint="index_mcp_pitch"
      multiplier="0.89"
      offset="0" />
  </joint>
  <link
    name="middle_proximal">
    <inertial>
      <origin
        xyz="-0.00208661081773556 -4.93451838476378E-06 0.0172736805321904"
        rpy="0 0 0" />
      <mass
        value="0.00253175497594429" />
      <inertia
        ixx="2.65989683690695E-07"
        ixy="-3.58343951791586E-11"
        ixz="4.31048601085216E-08"
        iyy="2.72915006047006E-07"
        iyz="1.75718024412593E-10"
        izz="8.56020467202518E-08" />
    </inertial>
    <visual>
      <origin
        xyz="0 0 0"
        rpy="-1.57079632 0 0" />
      <geometry>
        <mesh
          filename="meshes/middle_proximal.STL" />
      </geometry>
      <material
        name="">
        <color
          rgba="0.164705882352941 0.282352941176471 0.443137254901961 1" />
      </material>
    </visual>
    <collision>
      <origin
        xyz="0 0 0"
        rpy="0 0 0" />
      <geometry>
        <mesh
          filename="meshes/middle_proximal.STL" />
      </geometry>
    </collision>
  </link>
  <joint
    name="middle_mcp_pitch"
    type="revolute">
    <origin
      xyz="0.00052576 0.00634 0.1027"
      rpy="0 0 0" />
    <parent
      link="hand_base_link" />
    <child
      link="middle_proximal" />
    <axis
      xyz="0 1 0" />
    <limit
      lower="0"
      upper="1.60"
      effort="100"
      velocity="1" />
  </joint>
  <link
    name="middle_distal">
    <inertial>
      <origin
        xyz="0.00658940304809306 -4.5885743593238E-06 0.0194434523296449"
        rpy="0 0 0" />
      <mass
        value="0.00376786259758948" />
      <inertia
        ixx="3.221153658306E-07"
        ixy="1.02639617308432E-11"
        ixz="-1.14363547272711E-07"
        iyy="3.65130723083104E-07"
        iyz="-1.96904618797577E-10"
        izz="1.24256787913797E-07" />
    </inertial>
    <visual>
      <origin
        xyz="0 0 0"
        rpy="-1.57079632 0 0" />
      <geometry>
        <mesh
          filename="meshes/middle_distal.STL" />
      </geometry>
      <material
        name="">
        <color
          rgba="0.164705882352941 0.282352941176471 0.443137254901961 1" />
      </material>
    </visual>
    <collision>
      <origin
        xyz="0 0 0"
        rpy="0 0 0" />
      <geometry>
        <mesh
          filename="meshes/middle_distal.STL" />
      </geometry>
    </collision>
  </link>
  <joint
    name="middle_dip"
    type="revolute">
    <origin
      xyz="-0.0052516 0 0.036625"
      rpy="0 0 0" />
    <parent
      link="middle_proximal" />
    <child
      link="middle_distal" />
    <axis
      xyz="0 1 0" />
    <limit
      lower="0"
      upper="1.43"
      effort="100"
      velocity="1" />
    <mimic
      joint="middle_mcp_pitch"
      multiplier="0.89"
      offset="0" />
  </joint>
  <link
    name="ring_proximal">
    <inertial>
      <origin
        xyz="-0.00208654311325356 -4.98538564003281E-06 0.0172736743497407"
        rpy="0 0 0" />
      <mass
        value="0.00253170963529411" />
      <inertia
        ixx="2.6598913795678E-07"
        ixy="-3.62757108675266E-11"
        ixz="4.31050611555507E-08"
        iyy="2.72914417061517E-07"
        iyz="1.75554984053478E-10"
        izz="8.56012458677515E-08" />
    </inertial>
    <visual>
      <origin
        xyz="0 0 0"
        rpy="-1.57079632 0 0" />
      <geometry>
        <mesh
          filename="meshes/ring_proximal.STL" />
      </geometry>
      <material
        name="">
        <color
          rgba="0.980392156862745 0.780392156862745 0.627450980392157 1" />
      </material>
    </visual>
    <collision>
      <origin
        xyz="0 0 0"
        rpy="0 0 0" />
      <geometry>
        <mesh
          filename="meshes/ring_proximal.STL" />
      </geometry>
    </collision>
  </link>
  <joint
    name="ring_mcp_pitch"
    type="revolute">
    <origin
      xyz="0.0010258 -0.011135 0.098767"
      rpy="0.05236 0 0" />
    <parent
      link="hand_base_link" />
    <child
      link="ring_proximal" />
    <axis
      xyz="0 1 0" />
    <limit
      lower="0"
      upper="1.60"
      effort="100"
      velocity="1" />
  </joint>
  <link
    name="ring_distal">
    <inertial>
      <origin
        xyz="0.00658940273069729 -4.56628863591824E-06 0.0194435005686854"
        rpy="0 0 0" />
      <mass
        value="0.0037678395356105" />
      <inertia
        ixx="3.22112632437858E-07"
        ixy="1.01848408913558E-11"
        ixz="-1.1436348915342E-07"
        iyy="3.65128262095686E-07"
        iyz="-1.96145632992445E-10"
        izz="1.24256284608064E-07" />
    </inertial>
    <visual>
      <origin
        xyz="0 0 0"
        rpy="-1.57079632 0 0" />
      <geometry>
        <mesh
          filename="meshes/ring_distal.STL" />
      </geometry>
      <material
        name="">
        <color
          rgba="0.164705882352941 0.282352941176471 0.443137254901961 1" />
      </material>
    </visual>
    <collision>
      <origin
        xyz="0 0 0"
        rpy="0 0 0" />
      <geometry>
        <mesh
          filename="meshes/ring_distal.STL" />
      </geometry>
    </collision>
  </link>
  <joint
    name="ring_dip"
    type="revolute">
    <origin
      xyz="-0.0052516 0 0.036625"
      rpy="0 0 0" />
    <parent
      link="ring_proximal" />
    <child
      link="ring_distal" />
    <axis
      xyz="0 1 0" />
    <limit
      lower="0"
      upper="1.43"
      effort="100"
      velocity="1" />
    <mimic
      joint="ring_mcp_pitch"
      multiplier="0.89"
      offset="0" />
  </joint>
  <link
    name="pinky_proximal">
    <inertial>
      <origin
        xyz="-0.00208649034130813 -5.02314582560837E-06 0.0172736680793697"
        rpy="0 0 0" />
      <mass
        value="0.00253167400540778" />
      <inertia
        ixx="2.65988718820404E-07"
        ixy="-3.66012295280295E-11"
        ixz="4.31052220484445E-08"
        iyy="2.72913936904813E-07"
        iyz="1.75447396222308E-10"
        izz="8.56006424720129E-08" />
    </inertial>
    <visual>
      <origin
        xyz="0 0 0"
        rpy="-1.57079632 0 0" />
      <geometry>
        <mesh
          filename="meshes/pinky_proximal.STL" />
      </geometry>
      <material
        name="">
        <color
          rgba="0.980392156862745 0.780392156862745 0.627450980392157 1" />
      </material>
    </visual>
    <collision>
      <origin
        xyz="0 0 0"
        rpy="0 0 0" />
      <geometry>
        <mesh
          filename="meshes/pinky_proximal.STL" />
      </geometry>
    </collision>
  </link>
  <joint
    name="pinky_mcp_pitch"
    type="revolute">
    <origin
      xyz="0.0024758 -0.028372 0.092741"
      rpy="0.087266 0 0" />
    <parent
      link="hand_base_link" />
    <child
      link="pinky_proximal" />
    <axis
      xyz="0 1 0" />
    <limit
      lower="0"
      upper="1.60"
      effort="100"
      velocity="1" />
  </joint>
  <link
    name="pinky_distal">
    <inertial>
      <origin
        xyz="0.00658940431519205 -4.55268314210333E-06 0.0194435341098305"
        rpy="0 0 0" />
      <mass
        value="0.00376782669873412" />
      <inertia
        ixx="3.22111112339498E-07"
        ixy="1.01707985908333E-11"
        ixz="-1.14363524419061E-07"
        iyy="3.65126916899176E-07"
        iyz="-1.95589215866356E-10"
        izz="1.24256004854426E-07" />
    </inertial>
    <visual>
      <origin
        xyz="0 0 0"
        rpy="-1.57079632 0 0" />
      <geometry>
        <mesh
          filename="meshes/pinky_distal.STL" />
      </geometry>
      <material
        name="">
        <color
          rgba="0.164705882352941 0.282352941176471 0.443137254901961 1" />
      </material>
    </visual>
    <collision>
      <origin
        xyz="0 0 0"
        rpy="0 0 0" />
      <geometry>
        <mesh
          filename="meshes/pinky_distal.STL" />
      </geometry>
    </collision>
  </link>
  <joint
    name="pinky_dip"
    type="revolute">
    <origin
      xyz="-0.0052516 0 0.036625"
      rpy="0 0 0" />
    <parent
      link="pinky_proximal" />
    <child
      link="pinky_distal" />
    <axis
      xyz="0 1 0" />
    <limit
      lower="0"
      upper="1.43"
      effort="100"
      velocity="1" />
    <mimic
      joint="pinky_mcp_pitch"
      multiplier="0.89"
      offset="0" />
  </joint>
</robot>